Workbook

Sheet Instructions
A1: PrePal Undergraduate User Acceptance Testing Workbook
A2: A structured template for recording functional testing, tri-model GPA validation, usability feedback, and defects.
A4: How to use this workbook
A5: 1 | B5: Assign an anonymous Participant Code | C5: Use codes such as UAT-001. Do not record a student's name, campus ID, password, or private mental-health details in this workbook.
A6: 2 | B6: Register the test device | C6: Complete one row in Test Participants, including degree programme, batch/year, Android version, and device model.
A7: 3 | B7: Select test cases | C7: Use the Core test cases first. Extended cases are useful for additional boundary, reliability, security, and compatibility testing.
A8: 4 | B8: Execute and record | C8: Create a row in Test Execution for each test performed. Select the Test Case ID; area, model, steps, and expected result populate automatically.
A9: 5 | B9: Validate all three GPA models | C9: Run the prepared scenarios in Model Validation. Record the model selected by the app, two prediction runs, warnings shown, and explanation helpfulness.
A10: 6 | B10: Collect usability feedback | C10: Each participant completes one row in Usability Feedback using the 1–5 scale. Question wording is in Lists & Guide.
A11: 7 | B11: Log defects | C11: For every failed case, create a Defect ID in Defect Log and copy that ID back to the Test Execution row.
A12: 8 | B12: Review results | C12: Dashboard formulas update automatically as testing records are added.
A14: Tri-model routing used in this workbook
A15: Model | B15: Student stage | C15: Data availability | D15: Expected routing
A16: Model A | B16: Pre-CA / baseline stage | C16: Current CA marks are not yet available | D16: The app selects the baseline prediction model
A17: Model B | B17: New student at mid-semester | C17: CA marks are available but no previous university GPA exists | D17: The app selects the new-student mid-semester model
A18: Model C | B18: Returning student at mid-semester | C18: Previous GPA and current CA marks are both available | D18: The app selects the comprehensive returning-student model
A20: Important: Confirm the three model-routing definitions above against the final deployed PrePal build before formal data collection. If your final implementation uses different input availability, update the catalogue and Model Validation rules first.
A23: Result and severity definitions
A24: Term | B24: Meaning | C24: Term | D24: Meaning
A25: Pass | B25: Actual result matches the expected result. | C25: Critical | D25: Crash, data exposure, account crossover, or prediction feature cannot be used.
A26: Fail | B26: Actual result does not match the expected result. | C26: High | D26: Major feature fails; no reasonable workaround.
A27: Blocked | B27: The case cannot be completed because another issue prevents it. | C27: Medium | D27: Feature is impaired, but a workaround exists.
A28: Not Applicable | B28: The test does not apply to this participant/device/model. | C28: Low | D28: Minor visual, wording, or convenience issue.
A29: Not Run | B29: The test has not yet been executed. | C29: Retest | D29: Run the failed case again after the defect is fixed.
A31: Ethics note: Use synthetic DASS-21 answers and synthetic academic values for system testing. The workbook is for software evaluation, not clinical diagnosis. Any real participant distress should be handled through the campus's approved support process.

Sheet Test Participants
A1: Test Participants
A2: One anonymous row per undergraduate tester. Avoid names, student IDs, passwords, and identifiable mental-health information.
A4: Input cells are intentionally left blank. Use Participant Codes such as UAT-001, UAT-002, and so on.
A5: Participant Code | B5: Degree Programme | C5: Batch | D5: Year of Study | E5: Semester | F5: Android Version | G5: Device Model | H5: Prior GPA-tool Experience | I5: Consent Confirmed | J5: Test Date | K5: Execution Completion %
K6: =IF($A6="","",IFERROR(COUNTIFS('Test Execution'!$B$6:$B$205,$A6,'Test Execution'!$I$6:$I$205,"<>Not Run",'Test Execution'!$I$6:$I$205,"<>")/COUNTA('Test Case Catalogue'!$A$6:$A$90),0))
K7: =IF($A7="","",IFERROR(COUNTIFS('Test Execution'!$B$6:$B$205,$A7,'Test Execution'!$I$6:$I$205,"<>Not Run",'Test Execution'!$I$6:$I$205,"<>")/COUNTA('Test Case Catalogue'!$A$6:$A$90),0))
K8: =IF($A8="","",IFERROR(COUNTIFS('Test Execution'!$B$6:$B$205,$A8,'Test Execution'!$I$6:$I$205,"<>Not Run",'Test Execution'!$I$6:$I$205,"<>")/COUNTA('Test Case Catalogue'!$A$6:$A$90),0))
K9: =IF($A9="","",IFERROR(COUNTIFS('Test Execution'!$B$6:$B$205,$A9,'Test Execution'!$I$6:$I$205,"<>Not Run",'Test Execution'!$I$6:$I$205,"<>")/COUNTA('Test Case Catalogue'!$A$6:$A$90),0))
K10: =IF($A10="","",IFERROR(COUNTIFS('Test Execution'!$B$6:$B$205,$A10,'Test Execution'!$I$6:$I$205,"<>Not Run",'Test Execution'!$I$6:$I$205,"<>")/COUNTA('Test Case Catalogue'!$A$6:$A$90),0))
K11: =IF($A11="","",IFERROR(COUNTIFS('Test Execution'!$B$6:$B$205,$A11,'Test Execution'!$I$6:$I$205,"<>Not Run",'Test Execution'!$I$6:$I$205,"<>")/COUNTA('Test Case Catalogue'!$A$6:$A$90),0))
K12: =IF($A12="","",IFERROR(COUNTIFS('Test Execution'!$B$6:$B$205,$A12,'Test Execution'!$I$6:$I$205,"<>Not Run",'Test Execution'!$I$6:$I$205,"<>")/COUNTA('Test Case Catalogue'!$A$6:$A$90),0))
K13: =IF($A13="","",IFERROR(COUNTIFS('Test Execution'!$B$6:$B$205,$A13,'Test Execution'!$I$6:$I$205,"<>Not Run",'Test Execution'!$I$6:$I$205,"<>")/COUNTA('Test Case Catalogue'!$A$6:$A$90),0))
K14: =IF($A14="","",IFERROR(COUNTIFS('Test Execution'!$B$6:$B$205,$A14,'Test Execution'!$I$6:$I$205,"<>Not Run",'Test Execution'!$I$6:$I$205,"<>")/COUNTA('Test Case Catalogue'!$A$6:$A$90),0))
K15: =IF($A15="","",IFERROR(COUNTIFS('Test Execution'!$B$6:$B$205,$A15,'Test Execution'!$I$6:$I$205,"<>Not Run",'Test Execution'!$I$6:$I$205,"<>")/COUNTA('Test Case Catalogue'!$A$6:$A$90),0))
K16: =IF($A16="","",IFERROR(COUNTIFS('Test Execution'!$B$6:$B$205,$A16,'Test Execution'!$I$6:$I$205,"<>Not Run",'Test Execution'!$I$6:$I$205,"<>")/COUNTA('Test Case Catalogue'!$A$6:$A$90),0))
K17: =IF($A17="","",IFERROR(COUNTIFS('Test Execution'!$B$6:$B$205,$A17,'Test Execution'!$I$6:$I$205,"<>Not Run",'Test Execution'!$I$6:$I$205,"<>")/COUNTA('Test Case Catalogue'!$A$6:$A$90),0))
... K55: =IF($A55="","",IFERROR(COUNTIFS('Test Execution'!$B$6:$B$205,$A55,'Test Execution'!$I$6:$I$205,"<>Not Run",'Test Execution'!$I$6:$I$205,"<>")/COUNTA('Test Case Catalogue'!$A$6:$A$90),0))

Sheet Test Case Catalogue
A1: PrePal Student-App Test Case Catalogue
A2: Core and extended test cases for undergraduate user acceptance testing. Administrator-only functions are outside this catalogue.
A4: Core = recommended for every participant. Extended = run on selected devices/participants or by the researcher for deeper coverage.
A5: Test Case ID | B5: Area | C5: Feature | D5: Applicable Model | E5: Test Type | F5: Priority | G5: Preconditions | H5: Test Data | I5: Test Steps | J5: Expected Result | K5: Requirement / Rule | L5: Run Group | M5: Notes
A6: TC-001 | B6: Access | C6: App launch | D6: All | E6: Positive | F6: Critical | G6: PrePal is installed on a supported Android device. | H6: None | I6: Open PrePal from the device launcher. | J6: The app opens without crashing and shows the correct first screen. | K6: Availability | L6: Core | M6: Record launch time if noticeably slow.
A7: TC-002 | B7: Access | C7: Valid student login | D7: All | E7: Positive | F7: An active student test account exists. | G7: Valid test username and password | H7: Enter valid credentials and select Login. | I7: The student is authenticated and the student home screen opens. | J7: Authentication | K7: Core | L7: Use only a test account.
A8: TC-003 | B8: Access | C8: Invalid password | D8: All | E8: Negative | F8: A valid student test account exists. | G8: Valid username; incorrect password | H8: Attempt login with the wrong password. | I8: Access is denied and a clear, non-sensitive error is displayed. | J8: Authentication security | K8: Core | L8: The error must not reveal the stored password.
A9: TC-004 | B9: Access | C9: Missing login field | D9: All | E9: Negative | F9: Login screen is open. | G9: Blank username or password | H9: Leave one required field blank and select Login. | I9: Submission is prevented and the missing field is identified. | J9: Input validation | K9: Core
A10: TC-005 | B10: Access | C10: Logout and session closure | D10: All | E10: Security | F10: The student is logged in. | G10: None | H10: Log out, then use Back or reopen a protected screen. | I10: The session is closed and protected student data cannot be reopened without login. | J10: Session security | K10: Core
A11: TC-006 | B11: Questionnaire | C11: Required questions displayed | D11: All | E11: Positive | F11: The student is logged in and prediction questionnaire is available. | G11: None | H11: Open the academic questionnaire and review all sections. | I11: All academic, behavioral, sleep, and DASS-21 items required by the selected flow are visible and understandable. | J11: Complete data collection | K11: Core
A12: TC-007 | B12: Questionnaire | C12: Blank required answer | D12: All | E12: Negative | F12: Questionnaire is open. | G12: Leave one mandatory item unanswered | H12: Attempt to continue or submit. | I12: Submission is prevented and the unanswered item is clearly identified. | J12: Completeness validation | K12: Core
A13: TC-008 | B13: Questionnaire | C13: Academic numeric ranges | D13: All | E13: Boundary | F13: Questionnaire is open. | G13: Use values outside configured limits | H13: Enter an out-of-range GPA, mark, attendance, study-hour, or sleep value. | I13: The invalid value is rejected or a clear correction message is shown. | J13: Range validation | K13: Core
A14: TC-009 | B14: Questionnaire | C14: Decimal input handling | D14: All | E14: Boundary | F14: Questionnaire is open. | G14: GPA 3.45; attendance 79.9; sleep 7.5 | H14: Enter valid decimal values and continue. | I14: Valid decimal values are accepted without unintended rounding before prediction. | J14: Numeric precision | K14: Extended
A15: TC-010 | B15: Questionnaire | C15: Valid CA marks | D15: Model B / Model C | E15: Positive | F15: The mid-semester questionnaire is open. | G15: Mid mark 16/20; assignment mark 17/20 | H15: Enter both marks and continue. | I15: Both valid marks are accepted and used in the applicable model. | J15: CA input | K15: Core
A16: TC-011 | B16: Questionnaire | C16: Invalid CA marks | D16: Model B / Model C | E16: Negative | F16: The mid-semester questionnaire is open. | G16: -1 or 21 when each mark is out of 20 | H16: Enter invalid CA marks and submit. | I16: Submission is prevented and the allowed mark range is explained. | J16: CA range validation | K16: Core
A17: TC-012 | B17: Questionnaire | C17: Updated answers refresh output | D17: All | E17: Reliability | F17: A prediction has already been generated. | G17: Change attendance or study hours | H17: Edit one input and generate the prediction again. | I17: The new prediction, reasons, and warnings reflect the revised values rather than stale data. | J17: Data freshness | K17: Core
A18: TC-013 | B18: Model Routing | C18: Pre-CA profile routes to Model A | D18: Model A | E18: Functional | F18: A profile is created without current CA marks. | G18: No mid or assignment marks | H18: Complete the available baseline inputs and request a prediction. | I18: The app selects Model A and does not require current CA marks. | J18: Lifecycle-sensitive routing | K18: Core | L18: Confirm against final build.
A19: TC-014 | B19: Model Routing | C19: New student with CA routes to Model B | D19: Model B | E19: Functional | F19: A new student has current CA marks but no previous university GPA. | G19: Mid 15; assignment 14; previous GPA unavailable | H19: Complete the questionnaire and request a prediction. | I19: The app selects Model B and generates a result without demanding a previous GPA. | J19: Lifecycle-sensitive routing | K19: Core
A20: TC-015 | B20: Model Routing | C20: Returning student with GPA and CA routes to Model C | D20: Model C | E20: Functional | F20: A returning student has previous GPA and current CA marks. | G20: Previous GPA 3.10; mid 15; assignment 16 | H20: Complete the questionnaire and request a prediction. | I20: The app selects Model C and includes both historical GPA and current CA data. | J20: Lifecycle-sensitive routing | K20: Core
A21: TC-016 | B21: Model Routing | C21: Incomplete model inputs | D21: Model B / Model C | E21: Negative | F21: Only part of the model-specific data is entered. | G21: Mid mark entered; assignment mark blank | H21: Request a prediction. | I21: The app identifies the missing model input and does not silently route using incomplete data. | J21: Routing validation | K21: Core
A22: TC-017 | B22: GPA Prediction | C22: Model A standard profile | D22: Model A | E22: Positive | F22: Model A is selected. | G22: Attendance 85%; adequate study; sleep 7.5; low/moderate stress | H22: Generate a baseline prediction. | I22: A numeric GPA between 0.00 and 4.00 is returned with the model name and explanation. | J22: Prediction output | K22: Core
A23: TC-018 | B23: GPA Prediction | C23: Model A strong profile | D23: Model A | E23: Positive | F23: Model A is selected. | G23: Attendance 95%; strong study; sleep 8; low stress | H23: Generate a prediction and review explanations. | I23: The result is within GPA limits and positive factors are reflected in the explanation. | J23: Prediction reasonableness | K23: Extended | L23: Do not expect an exact GPA without model coefficients.
A24: TC-019 | B24: GPA Prediction | C24: Model A at-risk profile | D24: Model A | E24: Positive | F24: Model A is selected. | G24: Attendance 70%; low study; sleep 5; elevated stress | H24: Generate a prediction and review warnings. | I24: The result remains within GPA limits and relevant risk factors are highlighted. | J24: Risk identification | K24: Core
A25: TC-020 | B25: GPA Prediction | C25: Model A repeated input | D25: Model A | E25: Reliability | F25: A Model A prediction can be generated. | G25: Use identical inputs twice | H25: Generate twice without changing any value. | I25: Both runs return the same GPA within an accepted display tolerance of 0.01. | J25: Deterministic inference | K25: Extended
A26: TC-021 | B26: GPA Prediction | C26: Model A explanation | D26: Model A | E26: Usability | F26: A Model A prediction is displayed. | G26: None | H26: Open the reasons or explanation section. | I26: The explanation names understandable factors and does not claim certainty about the final result. | J26: Explainability | K26: Core
A27: TC-022 | B27: GPA Prediction | C27: Model A GPA limit | D27: Model A | E27: Boundary | F27: Model A is selected. | G27: Use extreme but valid inputs | H27: Generate a prediction. | I27: The displayed GPA is never below 0.00 or above 4.00. | J27: GPA scale 0–4 | K27: Core
A28: TC-023 | B28: GPA Prediction | C28: Model B standard profile | D28: Model B | E28: Positive | F28: Model B is selected. | G28: Mid 14; assignment 15; attendance 85%; balanced behavior | H28: Generate a prediction. | I28: A numeric GPA from 0.00 to 4.00 is returned and Model B is identified. | J28: Prediction output | K28: Core
A29: TC-024 | B29: GPA Prediction | C29: Model B minimum CA boundary | D29: Model B | E29: Boundary | F29: Model B is selected. | G29: Mid 0; assignment 0 | H29: Generate a prediction. | I29: Zero marks are accepted as valid boundary values and the output remains within the GPA scale. | J29: CA boundary | K29: Extended
A30: TC-025 | B30: GPA Prediction | C30: Model B maximum CA boundary | D30: Model B | E30: Boundary | F30: Model B is selected. | G30: Mid 20; assignment 20 | H30: Generate a prediction. | I30: Maximum valid marks are accepted and the output does not exceed 4.00. | J30: CA boundary | K30: Core
A31: TC-026 | B31: GPA Prediction | C31: Model B negative CA value | D31: Model B | E31: Negative | F31: Model B questionnaire is open. | G31: Mid -1 | H31: Attempt to continue. | I31: The negative value is rejected before prediction. | J31: CA validation | K31: Extended
A32: TC-027 | B32: GPA Prediction | C32: Model B CA above maximum | D32: Model B | E32: Negative | F32: Model B questionnaire is open. | G32: Assignment 21/20 | H32: Attempt to continue. | I32: The value above the maximum is rejected before prediction. | J32: CA validation | K32: Core
A33: TC-028 | B33: GPA Prediction | C33: Model B repeatability | D33: Model B | E33: Reliability | F33: A Model B prediction can be generated. | G33: Use identical valid inputs twice | H33: Generate the prediction twice. | I33: The two GPA results match within 0.01 and warnings do not change unexpectedly. | J33: Deterministic inference | K33: Extended
A34: TC-029 | B34: GPA Prediction | C34: Model B explanation | D34: Model B | E34: Usability | F34: A Model B result is displayed. | G34: None | H34: Review the prediction explanation. | I34: The explanation appropriately refers to current CA and behavioral factors, without referring to a nonexistent previous GPA. | J34: Explainability | K34: Core
A35: TC-030 | B35: GPA Prediction | C35: Model C standard profile | D35: Model C | E35: Positive | F35: Model C is selected. | G35: Previous GPA 3.10; mid 15; assignment 16; attendance 88% | H35: Generate a prediction. | I35: A numeric GPA from 0.00 to 4.00 is returned and Model C is identified. | J35: Prediction output | K35: Core
... A44: TC-039 | B44: Warnings | C44: High attendance | D44: All | E44: Positive | F44: A prediction questionnaire is open. | G44: Attendance 90% or above | H44: Generate the result. | I44: No incorrect below-threshold warning is shown; attendance may be recognized positively. | J44: Warning accuracy | K44: Extended
A45: TC-040 | B45: Warnings | C45: Study hours below configured SLQF expectation | D45: All | E45: Boundary | F45: The student's semester/credit context is available. | G45: A value below the app's calculated weekly expectation | H45: Generate the result. | I45: The app displays the configured study-effort warning and explains the expected benchmark. | J45: SLQF-based warning | K45: Core | L45: Verify the deployed credit-based calculation.
A46: TC-041 | B46: Warnings | C46: Study hours meet configured expectation | D46: All | E46: Positive | F46: The student's semester/credit context is available. | G46: A value equal to or above the app's calculated weekly expectation | H46: Generate the result. | I46: No incorrect below-expectation warning is shown. | J46: Warning accuracy | K46: Extended
A47: TC-042 | B47: Warnings | C47: Recommended sleep range | D47: All | E47: Boundary | F47: Questionnaire is open. | G47: Sleep 7.0–9.0 hours/day | H47: Generate the result. | I47: No incorrect insufficient-sleep warning is shown for a value inside the configured healthy range. | J47: Sleep warning | K47: Core
A48: TC-043 | B48: Warnings | C48: Low sleep | D48: All | E48: Boundary | F48: Questionnaire is open. | G48: Sleep 6.9 hours/day or lower | H48: Generate the result. | I48: A clear sleep-related risk or guidance message is shown. | J48: Sleep warning | K48: Core
A49: TC-044 | B49: Warnings | C49: Multiple simultaneous risks | D49: All | E49: Functional | F49: Questionnaire is open. | G49: Attendance below 80%; low study; low sleep; elevated stress | H49: Generate the result. | I49: All applicable warnings are displayed without overwriting, clipping, or contradicting one another. | J49: Combined warning engine | K49: Core
...

Sheet Test Execution
A1: Test Execution Log
A2: One row per test execution. Select a Test Case ID; the area, model, steps, and expected result populate automatically.
A4: Editable columns: Execution ID, Participant Code, Test Case ID, Actual Result, Status, Test Date, Evidence, Defect ID, Severity, Retest Status, and Comments.
A5: Execution ID | B5: Participant Code | C5: Test Case ID | D5: Area (Auto) | E5: Applicable Model (Auto) | F5: Test Steps (Auto) | G5: Expected Result (Auto) | H5: Actual Result / Observation | I5: Status | J5: Test Date | K5: Evidence / Screenshot Ref | L5: Defect ID | M5: Severity if Failed | N5: Retest Status | O5: Comments
D6: =IF($C6="","",IFERROR(VLOOKUP($C6,'Test Case Catalogue'!$A$6:$M$90,2,FALSE),"")) | E6: =IF($C6="","",IFERROR(VLOOKUP($C6,'Test Case Catalogue'!$A$6:$M$90,4,FALSE),"")) | F6: =IF($C6="","",IFERROR(VLOOKUP($C6,'Test Case Catalogue'!$A$6:$M$90,9,FALSE),"")) | G6: =IF($C6="","",IFERROR(VLOOKUP($C6,'Test Case Catalogue'!$A$6:$M$90,10,FALSE),""))
D7: =IF($C7="","",IFERROR(VLOOKUP($C7,'Test Case Catalogue'!$A$6:$M$90,2,FALSE),"")) | E7: =IF($C7="","",IFERROR(VLOOKUP($C7,'Test Case Catalogue'!$A$6:$M$90,4,FALSE),"")) | F7: =IF($C7="","",IFERROR(VLOOKUP($C7,'Test Case Catalogue'!$A$6:$M$90,9,FALSE),"")) | G7: =IF($C7="","",IFERROR(VLOOKUP($C7,'Test Case Catalogue'!$A$6:$M$90,10,FALSE),""))
D8: =IF($C8="","",IFERROR(VLOOKUP($C8,'Test Case Catalogue'!$A$6:$M$90,2,FALSE),"")) | E8: =IF($C8="","",IFERROR(VLOOKUP($C8,'Test Case Catalogue'!$A$6:$M$90,4,FALSE),"")) | F8: =IF($C8="","",IFERROR(VLOOKUP($C8,'Test Case Catalogue'!$A$6:$M$90,9,FALSE),"")) | G8: =IF($C8="","",IFERROR(VLOOKUP($C8,'Test Case Catalogue'!$A$6:$M$90,10,FALSE),""))
D9: =IF($C9="","",IFERROR(VLOOKUP($C9,'Test Case Catalogue'!$A$6:$M$90,2,FALSE),"")) | E9: =IF($C9="","",IFERROR(VLOOKUP($C9,'Test Case Catalogue'!$A$6:$M$90,4,FALSE),"")) | F9: =IF($C9="","",IFERROR(VLOOKUP($C9,'Test Case Catalogue'!$A$6:$M$90,9,FALSE),"")) | G9: =IF($C9="","",IFERROR(VLOOKUP($C9,'Test Case Catalogue'!$A$6:$M$90,10,FALSE),""))
D10: =IF($C10="","",IFERROR(VLOOKUP($C10,'Test Case Catalogue'!$A$6:$M$90,2,FALSE),"")) | E10: =IF($C10="","",IFERROR(VLOOKUP($C10,'Test Case Catalogue'!$A$6:$M$90,4,FALSE),"")) | F10: =IF($C10="","",IFERROR(VLOOKUP($C10,'Test Case Catalogue'!$A$6:$M$90,9,FALSE),"")) | G10: =IF($C10="","",IFERROR(VLOOKUP($C10,'Test Case Catalogue'!$A$6:$M$90,10,FALSE),""))
D11: =IF($C11="","",IFERROR(VLOOKUP($C11,'Test Case Catalogue'!$A$6:$M$90,2,FALSE),"")) | E11: =IF($C11="","",IFERROR(VLOOKUP($C11,'Test Case Catalogue'!$A$6:$M$90,4,FALSE),"")) | F11: =IF($C11="","",IFERROR(VLOOKUP($C11,'Test Case Catalogue'!$A$6:$M$90,9,FALSE),"")) | G11: =IF($C11="","",IFERROR(VLOOKUP($C11,'Test Case Catalogue'!$A$6:$M$90,10,FALSE),""))
D12: =IF($C12="","",IFERROR(VLOOKUP($C12,'Test Case Catalogue'!$A$6:$M$90,2,FALSE),"")) | E12: =IF($C12="","",IFERROR(VLOOKUP($C12,'Test Case Catalogue'!$A$6:$M$90,4,FALSE),"")) | F12: =IF($C12="","",IFERROR(VLOOKUP($C12,'Test Case Catalogue'!$A$6:$M$90,9,FALSE),"")) | G12: =IF($C12="","",IFERROR(VLOOKUP($C12,'Test Case Catalogue'!$A$6:$M$90,10,FALSE),""))
D13: =IF($C13="","",IFERROR(VLOOKUP($C13,'Test Case Catalogue'!$A$6:$M$90,2,FALSE),"")) | E13: =IF($C13="","",IFERROR(VLOOKUP($C13,'Test Case Catalogue'!$A$6:$M$90,4,FALSE),"")) | F13: =IF($C13="","",IFERROR(VLOOKUP($C13,'Test Case Catalogue'!$A$6:$M$90,9,FALSE),"")) | G13: =IF($C13="","",IFERROR(VLOOKUP($C13,'Test Case Catalogue'!$A$6:$M$90,10,FALSE),""))
D14: =IF($C14="","",IFERROR(VLOOKUP($C14,'Test Case Catalogue'!$A$6:$M$90,2,FALSE),"")) | E14: =IF($C14="","",IFERROR(VLOOKUP($C14,'Test Case Catalogue'!$A$6:$M$90,4,FALSE),"")) | F14: =IF($C14="","",IFERROR(VLOOKUP($C14,'Test Case Catalogue'!$A$6:$M$90,9,FALSE),"")) | G14: =IF($C14="","",IFERROR(VLOOKUP($C14,'Test Case Catalogue'!$A$6:$M$90,10,FALSE),""))
D15: =IF($C15="","",IFERROR(VLOOKUP($C15,'Test Case Catalogue'!$A$6:$M$90,2,FALSE),"")) | E15: =IF($C15="","",IFERROR(VLOOKUP($C15,'Test Case Catalogue'!$A$6:$M$90,4,FALSE),"")) | F15: =IF($C15="","",IFERROR(VLOOKUP($C15,'Test Case Catalogue'!$A$6:$M$90,9,FALSE),"")) | G15: =IF($C15="","",IFERROR(VLOOKUP($C15,'Test Case Catalogue'!$A$6:$M$90,10,FALSE),""))
D16: =IF($C16="","",IFERROR(VLOOKUP($C16,'Test Case Catalogue'!$A$6:$M$90,2,FALSE),"")) | E16: =IF($C16="","",IFERROR(VLOOKUP($C16,'Test Case Catalogue'!$A$6:$M$90,4,FALSE),"")) | F16: =IF($C16="","",IFERROR(VLOOKUP($C16,'Test Case Catalogue'!$A$6:$M$90,9,FALSE),"")) | G16: =IF($C16="","",IFERROR(VLOOKUP($C16,'Test Case Catalogue'!$A$6:$M$90,10,FALSE),""))
D17: =IF($C17="","",IFERROR(VLOOKUP($C17,'Test Case Catalogue'!$A$6:$M$90,2,FALSE),"")) | E17: =IF($C17="","",IFERROR(VLOOKUP($C17,'Test Case Catalogue'!$A$6:$M$90,4,FALSE),"")) | F17: =IF($C17="","",IFERROR(VLOOKUP($C17,'Test Case Catalogue'!$A$6:$M$90,9,FALSE),"")) | G17: =IF($C17="","",IFERROR(VLOOKUP($C17,'Test Case Catalogue'!$A$6:$M$90,10,FALSE),""))
... D205: =IF($C205="","",IFERROR(VLOOKUP($C205,'Test Case Catalogue'!$A$6:$M$90,2,FALSE),"")) | E205: =IF($C205="","",IFERROR(VLOOKUP($C205,'Test Case Catalogue'!$A$6:$M$90,4,FALSE),"")) | F205: =IF($C205="","",IFERROR(VLOOKUP($C205,'Test Case Catalogue'!$A$6:$M$90,9,FALSE),"")) | G205: =IF($C205="","",IFERROR(VLOOKUP($C205,'Test Case Catalogue'!$A$6:$M$90,10,FALSE),""))

Sheet Model Validation
A1: Tri-Model GPA Validation
A2: Prepared valid-input scenarios for checking model routing, GPA bounds, repeatability, attendance warnings, and explanation helpfulness.
A4: Run each prepared scenario in PrePal. Enter the Participant Code, model selected by the app, two predicted GPA results, whether the attendance warning appeared, and a 1–5 explanation rating.
A5: Scenario ID | B5: Participant Code | C5: Student Profile | D5: Previous GPA | E5: Mid Mark /20 | F5: Assignment Mark /20 | G5: Attendance % | H5: Study Hours / Week | I5: Sleep Hours / Day | J5: DASS-21 Stress Score | K5: Expected Model (Auto) | L5: App Selected Model | M5: Routing Check (Auto) | N5: Predicted GPA Run 1 | O5: Predicted GPA Run 2 | P5: Difference (Auto) | Q5: GPA Range Check (Auto) | R5: Repeatability Check (Auto) | S5: Attendance Warning Expected | T5: Attendance Warning Shown | U5: Warning Check (Auto) | V5: Explanation Helpful 1–5 | W5: Comments
A6: MV-A01 | C6: Pre-CA standard profile | G6: 85 | H6: 50 | I6: 7.5 | J6: 8 | K6: =IF($C6="","",IF(COUNTA($E6:$F6)=0,"Model A",IF(COUNTA($D6)=0,"Model B","Model C"))) -> Model A | M6: =IF($L6="","",IF($K6=$L6,"Pass","Fail")) | P6: =IF(OR($N6="",$O6=""),"",ABS($N6-$O6)) | Q6: =IF($N6="","",IF(AND($N6>=0,$N6<=4),"Pass","Fail")) | R6: =IF($P6="","",IF($P6<=0.01,"Pass","Fail")) | S6: =IF($G6="","",IF($G6<80,"Yes","No")) -> No | U6: =IF($T6="","",IF($S6=$T6,"Pass","Fail"))
A7: MV-A02 | C7: Pre-CA attendance boundary | G7: 80 | H7: 50 | I7: 7 | J7: 8 | K7: =IF($C7="","",IF(COUNTA($E7:$F7)=0,"Model A",IF(COUNTA($D7)=0,"Model B","Model C"))) -> Model A | M7: =IF($L7="","",IF($K7=$L7,"Pass","Fail")) | P7: =IF(OR($N7="",$O7=""),"",ABS($N7-$O7)) | Q7: =IF($N7="","",IF(AND($N7>=0,$N7<=4),"Pass","Fail")) | R7: =IF($P7="","",IF($P7<=0.01,"Pass","Fail")) | S7: =IF($G7="","",IF($G7<80,"Yes","No")) -> No | U7: =IF($T7="","",IF($S7=$T7,"Pass","Fail"))
A8: MV-A03 | C8: Pre-CA attendance risk | G8: 79.9 | H8: 40 | I8: 6.5 | J8: 16 | K8: =IF($C8="","",IF(COUNTA($E8:$F8)=0,"Model A",IF(COUNTA($D8)=0,"Model B","Model C"))) -> Model A | M8: =IF($L8="","",IF($K8=$L8,"Pass","Fail")) | P8: =IF(OR($N8="",$O8=""),"",ABS($N8-$O8)) | Q8: =IF($N8="","",IF(AND($N8>=0,$N8<=4),"Pass","Fail")) | R8: =IF($P8="","",IF($P8<=0.01,"Pass","Fail")) | S8: =IF($G8="","",IF($G8<80,"Yes","No")) -> Yes | U8: =IF($T8="","",IF($S8=$T8,"Pass","Fail"))
A9: MV-A04 | C9: Pre-CA combined-risk profile | G9: 70 | H9: 25 | I9: 5 | J9: 24 | K9: =IF($C9="","",IF(COUNTA($E9:$F9)=0,"Model A",IF(COUNTA($D9)=0,"Model B","Model C"))) -> Model A | M9: =IF($L9="","",IF($K9=$L9,"Pass","Fail")) | P9: =IF(OR($N9="",$O9=""),"",ABS($N9-$O9)) | Q9: =IF($N9="","",IF(AND($N9>=0,$N9<=4),"Pass","Fail")) | R9: =IF($P9="","",IF($P9<=0.01,"Pass","Fail")) | S9: =IF($G9="","",IF($G9<80,"Yes","No")) -> Yes | U9: =IF($T9="","",IF($S9=$T9,"Pass","Fail"))
A10: MV-B01 | C10: New student with strong CA | E10: 18 | F10: 18 | G10: 95 | H10: 55 | I10: 8 | J10: 4 | K10: =IF($C10="","",IF(COUNTA($E10:$F10)=0,"Model A",IF(COUNTA($D10)=0,"Model B","Model C"))) -> Model B | M10: =IF($L10="","",IF($K10=$L10,"Pass","Fail")) | P10: =IF(OR($N10="",$O10=""),"",ABS($N10-$O10)) | Q10: =IF($N10="","",IF(AND($N10>=0,$N10<=4),"Pass","Fail")) | R10: =IF($P10="","",IF($P10<=0.01,"Pass","Fail")) | S10: =IF($G10="","",IF($G10<80,"Yes","No")) -> No | U10: =IF($T10="","",IF($S10=$T10,"Pass","Fail"))
A11: MV-B02 | C11: New student with typical CA | E11: 14 | F11: 15 | G11: 85 | H11: 50 | I11: 7.5 | J11: 8 | K11: =IF($C11="","",IF(COUNTA($E11:$F11)=0,"Model A",IF(COUNTA($D11)=0,"Model B","Model C"))) -> Model B | M11: =IF($L11="","",IF($K11=$L11,"Pass","Fail")) | P11: =IF(OR($N11="",$O11=""),"",ABS($N11-$O11)) | Q11: =IF($N11="","",IF(AND($N11>=0,$N11<=4),"Pass","Fail")) | R11: =IF($P11="","",IF($P11<=0.01,"Pass","Fail")) | S11: =IF($G11="","",IF($G11<80,"Yes","No")) -> No | U11: =IF($T11="","",IF($S11=$T11,"Pass","Fail"))
A12: MV-B03 | C12: New student minimum CA boundary | E12: 0 | F12: 0 | G12: 80 | H12: 35 | I12: 7 | J12: 12 | K12: =IF($C12="","",IF(COUNTA($E12:$F12)=0,"Model A",IF(COUNTA($D12)=0,"Model B","Model C"))) -> Model B | M12: =IF($L12="","",IF($K12=$L12,"Pass","Fail")) | P12: =IF(OR($N12="",$O12=""),"",ABS($N12-$O12)) | Q12: =IF($N12="","",IF(AND($N12>=0,$N12<=4),"Pass","Fail")) | R12: =IF($P12="","",IF($P12<=0.01,"Pass","Fail")) | S12: =IF($G12="","",IF($G12<80,"Yes","No")) -> No | U12: =IF($T12="","",IF($S12=$T12,"Pass","Fail"))
A13: MV-B04 | C13: New student maximum CA boundary | E13: 20 | F13: 20 | G13: 90 | H13: 55 | I13: 8.5 | J13: 2 | K13: =IF($C13="","",IF(COUNTA($E13:$F13)=0,"Model A",IF(COUNTA($D13)=0,"Model B","Model C"))) -> Model B | M13: =IF($L13="","",IF($K13=$L13,"Pass","Fail")) | P13: =IF(OR($N13="",$O13=""),"",ABS($N13-$O13)) | Q13: =IF($N13="","",IF(AND($N13>=0,$N13<=4),"Pass","Fail")) | R13: =IF($P13="","",IF($P13<=0.01,"Pass","Fail")) | S13: =IF($G13="","",IF($G13<80,"Yes","No")) -> No | U13: =IF($T13="","",IF($S13=$T13,"Pass","Fail"))
A14: MV-C01 | C14: Returning student strong profile | D14: 3.7 | E14: 18 | F14: 18 | G14: 95 | H14: 55 | I14: 8 | J14: 4 | K14: =IF($C14="","",IF(COUNTA($E14:$F14)=0,"Model A",IF(COUNTA($D14)=0,"Model B","Model C"))) -> Model C | M14: =IF($L14="","",IF($K14=$L14,"Pass","Fail")) | P14: =IF(OR($N14="",$O14=""),"",ABS($N14-$O14)) | Q14: =IF($N14="","",IF(AND($N14>=0,$N14<=4),"Pass","Fail")) | R14: =IF($P14="","",IF($P14<=0.01,"Pass","Fail")) | S14: =IF($G14="","",IF($G14<80,"Yes","No")) -> No | U14: =IF($T14="","",IF($S14=$T14,"Pass","Fail"))
A15: MV-C02 | C15: Returning student typical profile | D15: 3.1 | E15: 15 | F15: 16 | G15: 85 | H15: 50 | I15: 7.5 | J15: 8 | K15: =IF($C15="","",IF(COUNTA($E15:$F15)=0,"Model A",IF(COUNTA($D15)=0,"Model B","Model C"))) -> Model C | M15: =IF($L15="","",IF($K15=$L15,"Pass","Fail")) | P15: =IF(OR($N15="",$O15=""),"",ABS($N15-$O15)) | Q15: =IF($N15="","",IF(AND($N15>=0,$N15<=4),"Pass","Fail")) | R15: =IF($P15="","",IF($P15<=0.01,"Pass","Fail")) | S15: =IF($G15="","",IF($G15<80,"Yes","No")) -> No | U15: =IF($T15="","",IF($S15=$T15,"Pass","Fail"))
A16: MV-C03 | C16: Returning student previous GPA minimum | D16: 0 | E16: 10 | F16: 10 | G16: 80 | H16: 40 | I16: 7 | J16: 12 | K16: =IF($C16="","",IF(COUNTA($E16:$F16)=0,"Model A",IF(COUNTA($D16)=0,"Model B","Model C"))) -> Model C | M16: =IF($L16="","",IF($K16=$L16,"Pass","Fail")) | P16: =IF(OR($N16="",$O16=""),"",ABS($N16-$O16)) | Q16: =IF($N16="","",IF(AND($N16>=0,$N16<=4),"Pass","Fail")) | R16: =IF($P16="","",IF($P16<=0.01,"Pass","Fail")) | S16: =IF($G16="","",IF($G16<80,"Yes","No")) -> No | U16: =IF($T16="","",IF($S16=$T16,"Pass","Fail"))
A17: MV-C04 | C17: Returning student previous GPA maximum | D17: 4 | E17: 20 | F17: 20 | G17: 95 | H17: 55 | I17: 8 | J17: 2 | K17: =IF($C17="","",IF(COUNTA($E17:$F17)=0,"Model A",IF(COUNTA($D17)=0,"Model B","Model C"))) -> Model C | M17: =IF($L17="","",IF($K17=$L17,"Pass","Fail")) | P17: =IF(OR($N17="",$O17=""),"",ABS($N17-$O17)) | Q17: =IF($N17="","",IF(AND($N17>=0,$N17<=4),"Pass","Fail")) | R17: =IF($P17="","",IF($P17<=0.01,"Pass","Fail")) | S17: =IF($G17="","",IF($G17<80,"Yes","No")) -> No | U17: =IF($T17="","",IF($S17=$T17,"Pass","Fail"))
A18: MV-C05 | C18: Returning student risk profile | D18: 2 | E18: 6 | F18: 7 | G18: 70 | H18: 25 | I18: 5 | J18: 24 | K18: =IF($C18="","",IF(COUNTA($E18:$F18)=0,"Model A",IF(COUNTA($D18)=0,"Model B","Model C"))) -> Model C | M18: =IF($L18="","",IF($K18=$L18,"Pass","Fail")) | P18: =IF(OR($N18="",$O18=""),"",ABS($N18-$O18)) | Q18: =IF($N18="","",IF(AND($N18>=0,$N18<=4),"Pass","Fail")) | R18: =IF($P18="","",IF($P18<=0.01,"Pass","Fail")) | S18: =IF($G18="","",IF($G18<80,"Yes","No")) -> Yes | U18: =IF($T18="","",IF($S18=$T18,"Pass","Fail"))
K19: =IF($C19="","",IF(COUNTA($E19:$F19)=0,"Model A",IF(COUNTA($D19)=0,"Model B","Model C"))) | M19: =IF($L19="","",IF($K19=$L19,"Pass","Fail")) | P19: =IF(OR($N19="",$O19=""),"",ABS($N19-$O19)) | Q19: =IF($N19="","",IF(AND($N19>=0,$N19<=4),"Pass","Fail")) | R19: =IF($P19="","",IF($P19<=0.01,"Pass","Fail")) | S19: =IF($G19="","",IF($G19<80,"Yes","No")) | U19: =IF($T19="","",IF($S19=$T19,"Pass","Fail"))
K20: =IF($C20="","",IF(COUNTA($E20:$F20)=0,"Model A",IF(COUNTA($D20)=0,"Model B","Model C"))) | M20: =IF($L20="","",IF($K20=$L20,"Pass","Fail")) | P20: =IF(OR($N20="",$O20=""),"",ABS($N20-$O20)) | Q20: =IF($N20="","",IF(AND($N20>=0,$N20<=4),"Pass","Fail")) | R20: =IF($P20="","",IF($P20<=0.01,"Pass","Fail")) | S20: =IF($G20="","",IF($G20<80,"Yes","No")) | U20: =IF($T20="","",IF($S20=$T20,"Pass","Fail"))
K21: =IF($C21="","",IF(COUNTA($E21:$F21)=0,"Model A",IF(COUNTA($D21)=0,"Model B","Model C"))) | M21: =IF($L21="","",IF($K21=$L21,"Pass","Fail")) | P21: =IF(OR($N21="",$O21=""),"",ABS($N21-$O21)) | Q21: =IF($N21="","",IF(AND($N21>=0,$N21<=4),"Pass","Fail")) | R21: =IF($P21="","",IF($P21<=0.01,"Pass","Fail")) | S21: =IF($G21="","",IF($G21<80,"Yes","No")) | U21: =IF($T21="","",IF($S21=$T21,"Pass","Fail"))
K22: =IF($C22="","",IF(COUNTA($E22:$F22)=0,"Model A",IF(COUNTA($D22)=0,"Model B","Model C"))) | M22: =IF($L22="","",IF($K22=$L22,"Pass","Fail")) | P22: =IF(OR($N22="",$O22=""),"",ABS($N22-$O22)) | Q22: =IF($N22="","",IF(AND($N22>=0,$N22<=4),"Pass","Fail")) | R22: =IF($P22="","",IF($P22<=0.01,"Pass","Fail")) | S22: =IF($G22="","",IF($G22<80,"Yes","No")) | U22: =IF($T22="","",IF($S22=$T22,"Pass","Fail"))
K23: =IF($C23="","",IF(COUNTA($E23:$F23)=0,"Model A",IF(COUNTA($D23)=0,"Model B","Model C"))) | M23: =IF($L23="","",IF($K23=$L23,"Pass","Fail")) | P23: =IF(OR($N23="",$O23=""),"",ABS($N23-$O23)) | Q23: =IF($N23="","",IF(AND($N23>=0,$N23<=4),"Pass","Fail")) | R23: =IF($P23="","",IF($P23<=0.01,"Pass","Fail")) | S23: =IF($G23="","",IF($G23<80,"Yes","No")) | U23: =IF($T23="","",IF($S23=$T23,"Pass","Fail"))
K24: =IF($C24="","",IF(COUNTA($E24:$F24)=0,"Model A",IF(COUNTA($D24)=0,"Model B","Model C"))) | M24: =IF($L24="","",IF($K24=$L24,"Pass","Fail")) | P24: =IF(OR($N24="",$O24=""),"",ABS($N24-$O24)) | Q24: =IF($N24="","",IF(AND($N24>=0,$N24<=4),"Pass","Fail")) | R24: =IF($P24="","",IF($P24<=0.01,"Pass","Fail")) | S24: =IF($G24="","",IF($G24<80,"Yes","No")) | U24: =IF($T24="","",IF($S24=$T24,"Pass","Fail"))
K25: =IF($C25="","",IF(COUNTA($E25:$F25)=0,"Model A",IF(COUNTA($D25)=0,"Model B","Model C"))) | M25: =IF($L25="","",IF($K25=$L25,"Pass","Fail")) | P25: =IF(OR($N25="",$O25=""),"",ABS($N25-$O25)) | Q25: =IF($N25="","",IF(AND($N25>=0,$N25<=4),"Pass","Fail")) | R25: =IF($P25="","",IF($P25<=0.01,"Pass","Fail")) | S25: =IF($G25="","",IF($G25<80,"Yes","No")) | U25: =IF($T25="","",IF($S25=$T25,"Pass","Fail"))
K26: =IF($C26="","",IF(COUNTA($E26:$F26)=0,"Model A",IF(COUNTA($D26)=0,"Model B","Model C"))) | M26: =IF($L26="","",IF($K26=$L26,"Pass","Fail")) | P26: =IF(OR($N26="",$O26=""),"",ABS($N26-$O26)) | Q26: =IF($N26="","",IF(AND($N26>=0,$N26<=4),"Pass","Fail")) | R26: =IF($P26="","",IF($P26<=0.01,"Pass","Fail")) | S26: =IF($G26="","",IF($G26<80,"Yes","No")) | U26: =IF($T26="","",IF($S26=$T26,"Pass","Fail"))
K27: =IF($C27="","",IF(COUNTA($E27:$F27)=0,"Model A",IF(COUNTA($D27)=0,"Model B","Model C"))) | M27: =IF($L27="","",IF($K27=$L27,"Pass","Fail")) | P27: =IF(OR($N27="",$O27=""),"",ABS($N27-$O27)) | Q27: =IF($N27="","",IF(AND($N27>=0,$N27<=4),"Pass","Fail")) | R27: =IF($P27="","",IF($P27<=0.01,"Pass","Fail")) | S27: =IF($G27="","",IF($G27<80,"Yes","No")) | U27: =IF($T27="","",IF($S27=$T27,"Pass","Fail"))
K28: =IF($C28="","",IF(COUNTA($E28:$F28)=0,"Model A",IF(COUNTA($D28)=0,"Model B","Model C"))) | M28: =IF($L28="","",IF($K28=$L28,"Pass","Fail")) | P28: =IF(OR($N28="",$O28=""),"",ABS($N28-$O28)) | Q28: =IF($N28="","",IF(AND($N28>=0,$N28<=4),"Pass","Fail")) | R28: =IF($P28="","",IF($P28<=0.01,"Pass","Fail")) | S28: =IF($G28="","",IF($G28<80,"Yes","No")) | U28: =IF($T28="","",IF($S28=$T28,"Pass","Fail"))
K29: =IF($C29="","",IF(COUNTA($E29:$F29)=0,"Model A",IF(COUNTA($D29)=0,"Model B","Model C"))) | M29: =IF($L29="","",IF($K29=$L29,"Pass","Fail")) | P29: =IF(OR($N29="",$O29=""),"",ABS($N29-$O29)) | Q29: =IF($N29="","",IF(AND($N29>=0,$N29<=4),"Pass","Fail")) | R29: =IF($P29="","",IF($P29<=0.01,"Pass","Fail")) | S29: =IF($G29="","",IF($G29<80,"Yes","No")) | U29: =IF($T29="","",IF($S29=$T29,"Pass","Fail"))
K30: =IF($C30="","",IF(COUNTA($E30:$F30)=0,"Model A",IF(COUNTA($D30)=0,"Model B","Model C"))) | M30: =IF($L30="","",IF($K30=$L30,"Pass","Fail")) | P30: =IF(OR($N30="",$O30=""),"",ABS($N30-$O30)) | Q30: =IF($N30="","",IF(AND($N30>=0,$N30<=4),"Pass","Fail")) | R30: =IF($P30="","",IF($P30<=0.01,"Pass","Fail")) | S30: =IF($G30="","",IF($G30<80,"Yes","No")) | U30: =IF($T30="","",IF($S30=$T30,"Pass","Fail"))
... K55: =IF($C55="","",IF(COUNTA($E55:$F55)=0,"Model A",IF(COUNTA($D55)=0,"Model B","Model C"))) | M55: =IF($L55="","",IF($K55=$L55,"Pass","Fail")) | P55: =IF(OR($N55="",$O55=""),"",ABS($N55-$O55)) | Q55: =IF($N55="","",IF(AND($N55>=0,$N55<=4),"Pass","Fail")) | R55: =IF($P55="","",IF($P55<=0.01,"Pass","Fail")) | S55: =IF($G55="","",IF($G55<80,"Yes","No")) | U55: =IF($T55="","",IF($S55=$T55,"Pass","Fail"))

Sheet Usability Feedback
A1: Undergraduate Usability Feedback
A2: Each participant completes one row after testing. Ratings: 1 = Strongly Disagree, 5 = Strongly Agree.
A4: Question wording is listed in Lists & Guide. Use Participant Code only. Q1–Q12 must be numeric ratings from 1 to 5.
A5: Participant Code | B5: Feedback Date | C5: Q1 | D5: Q2 | E5: Q3 | F5: Q4 | G5: Q5 | H5: Q6 | I5: Q7 | J5: Q8 | K5: Q9 | L5: Q10 | M5: Q11 | N5: Q12 | O5: Average Rating | P5: Would Recommend | Q5: Most Useful Feature | R5: Most Difficult Part | S5: Suggested Improvement
O6: =IF($A6="","",IFERROR(AVERAGE($C6:$N6),""))
O7: =IF($A7="","",IFERROR(AVERAGE($C7:$N7),""))
O8: =IF($A8="","",IFERROR(AVERAGE($C8:$N8),""))
O9: =IF($A9="","",IFERROR(AVERAGE($C9:$N9),""))
O10: =IF($A10="","",IFERROR(AVERAGE($C10:$N10),""))
O11: =IF($A11="","",IFERROR(AVERAGE($C11:$N11),""))
O12: =IF($A12="","",IFERROR(AVERAGE($C12:$N12),""))
O13: =IF($A13="","",IFERROR(AVERAGE($C13:$N13),""))
O14: =IF($A14="","",IFERROR(AVERAGE($C14:$N14),""))
O15: =IF($A15="","",IFERROR(AVERAGE($C15:$N15),""))
O16: =IF($A16="","",IFERROR(AVERAGE($C16:$N16),""))
O17: =IF($A17="","",IFERROR(AVERAGE($C17:$N17),""))
... O55: =IF($A55="","",IFERROR(AVERAGE($C55:$N55),""))

Sheet Defect Log
A1: Defect Log
A2: Record every material failure with reproducible steps, expected versus actual behavior, evidence, severity, and retest outcome.
A4: Suggested ID format: BUG-001, BUG-002, etc. Critical privacy or account-isolation issues should be reported immediately and testing should stop for the affected flow.
A5: Defect ID | B5: Related Execution ID | C5: Participant Code | D5: Area | E5: Model | F5: Short Title | G5: Description | H5: Reproduction Steps | I5: Expected Result | J5: Actual Result | K5: Severity | L5: Priority | M5: Status | N5: Reported Date | O5: Evidence Ref | P5: Resolution / Retest Notes

Sheet Dashboard
A1: PrePal UAT Dashboard
A2: Automatic summary of recorded test execution, model validation, usability feedback, and defects.
A4: Participants | D4: Tests Executed | G4: Pass Rate
A5: =COUNTIF('Test Participants'!$A$6:$A$55,"<>") -> 0 | D5: =COUNTIFS('Test Execution'!$I$6:$I$205,"<>",'Test Execution'!$I$6:$I$205,"<>Not Run") -> 0 | G5: =IFERROR(COUNTIF('Test Execution'!$I$6:$I$205,"Pass")/(COUNTIF('Test Execution'!$I$6:$I$205,"Pass")+COUNTIF('Test Execution'!$I$6:$I$205,"Fail")),0) -> 0
A8: Failed Tests | D8: Open Defects | G8: Average Usability
A9: =COUNTIF('Test Execution'!$I$6:$I$205,"Fail") -> 0 | D9: =COUNTIFS('Defect Log'!$A$6:$A$105,"<>",'Defect Log'!$M$6:$M$105,"<>Closed") -> 0 | G9: =IFERROR(AVERAGE('Usability Feedback'!$O$6:$O$55),0) -> 0
A13: Execution Status | B13: Count | D13: Model | E13: Rows with Results | F13: Routing Pass | G13: GPA Range Pass | H13: Repeatability Pass
A14: Pass | B14: =COUNTIF('Test Execution'!$I$6:$I$205,A14) -> 0 | D14: Model A | E14: =COUNTIFS('Model Validation'!$K$6:$K$55,$D14,'Model Validation'!$N$6:$N$55,"<>") -> 0 | F14: =COUNTIFS('Model Validation'!$K$6:$K$55,$D14,'Model Validation'!$M$6:$M$55,"Pass") -> 0 | G14: =COUNTIFS('Model Validation'!$K$6:$K$55,$D14,'Model Validation'!$Q$6:$Q$55,"Pass") -> 0 | H14: =COUNTIFS('Model Validation'!$K$6:$K$55,$D14,'Model Validation'!$R$6:$R$55,"Pass") -> 0
A15: Fail | B15: =COUNTIF('Test Execution'!$I$6:$I$205,A15) -> 0 | D15: Model B | E15: =COUNTIFS('Model Validation'!$K$6:$K$55,$D15,'Model Validation'!$N$6:$N$55,"<>") -> 0 | F15: =COUNTIFS('Model Validation'!$K$6:$K$55,$D15,'Model Validation'!$M$6:$M$55,"Pass") -> 0 | G15: =COUNTIFS('Model Validation'!$K$6:$K$55,$D15,'Model Validation'!$Q$6:$Q$55,"Pass") -> 0 | H15: =COUNTIFS('Model Validation'!$K$6:$K$55,$D15,'Model Validation'!$R$6:$R$55,"Pass") -> 0
A16: Blocked | B16: =COUNTIF('Test Execution'!$I$6:$I$205,A16) -> 0 | D16: Model C | E16: =COUNTIFS('Model Validation'!$K$6:$K$55,$D16,'Model Validation'!$N$6:$N$55,"<>") -> 0 | F16: =COUNTIFS('Model Validation'!$K$6:$K$55,$D16,'Model Validation'!$M$6:$M$55,"Pass") -> 0 | G16: =COUNTIFS('Model Validation'!$K$6:$K$55,$D16,'Model Validation'!$Q$6:$Q$55,"Pass") -> 0 | H16: =COUNTIFS('Model Validation'!$K$6:$K$55,$D16,'Model Validation'!$R$6:$R$55,"Pass") -> 0
A17: Not Applicable | B17: =COUNTIF('Test Execution'!$I$6:$I$205,A17) -> 0
A18: Not Run | B18: =COUNTIF('Test Execution'!$I$6:$I$205,A18) -> 0
A21: Question | B21: Usability Measure | C21: Average Rating | E21: Defect Severity | F21: Count
A22: Q1 | B22: Access and onboarding | C22: =IFERROR(AVERAGE('Usability Feedback'!$C$6:$C$55),0) -> 0 | E22: Critical | F22: =COUNTIF('Defect Log'!$K$6:$K$105,E22) -> 0
A23: Q2 | B23: Input clarity | C23: =IFERROR(AVERAGE('Usability Feedback'!$D$6:$D$55),0) -> 0 | E23: High | F23: =COUNTIF('Defect Log'!$K$6:$K$105,E23) -> 0
A24: Q3 | B24: Model-routing confidence | C24: =IFERROR(AVERAGE('Usability Feedback'!$E$6:$E$55),0) -> 0 | E24: Medium | F24: =COUNTIF('Defect Log'!$K$6:$K$105,E24) -> 0
A25: Q4 | B25: Prediction presentation | C25: =IFERROR(AVERAGE('Usability Feedback'!$F$6:$F$55),0) -> 0 | E25: Low | F25: =COUNTIF('Defect Log'!$K$6:$K$105,E25) -> 0
A26: Q5 | B26: Explainability | C26: =IFERROR(AVERAGE('Usability Feedback'!$G$6:$G$55),0) -> 0
A27: Q6 | B27: Warning usefulness | C27: =IFERROR(AVERAGE('Usability Feedback'!$H$6:$H$55),0) -> 0
A28: Q7 | B28: Mental-health screening usability | C28: =IFERROR(AVERAGE('Usability Feedback'!$I$6:$I$55),0) -> 0 | E28: Interpretation note A high UAT pass rate and positive usability feedback support system acceptance, but they do not independently prove machine-learning predictive accuracy. Report model accuracy separately using your labelled validation dataset and MAE, MSE, and R² metrics.
A29: Q8 | B29: Dashboard clarity | C29: =IFERROR(AVERAGE('Usability Feedback'!$J$6:$J$55),0) -> 0
A30: Q9 | B30: AI support usefulness | C30: =IFERROR(AVERAGE('Usability Feedback'!$K$6:$K$55),0) -> 0
A31: Q10 | B31: Supporting features | C31: =IFERROR(AVERAGE('Usability Feedback'!$L$6:$L$55),0) -> 0
A32: Q11 | B32: Performance and reliability | C32: =IFERROR(AVERAGE('Usability Feedback'!$M$6:$M$55),0) -> 0
A33: Q12 | B33: Overall acceptance | C33: =IFERROR(AVERAGE('Usability Feedback'!$N$6:$N$55),0) -> 0

Sheet Lists & Guide
A1: Lists, Rating Guide, and Research Notes
A2: Reference definitions used by the workbook. Keep this sheet when distributing or consolidating test files.
A4: Question ID | B4: Usability statement | C4: Interpretation | E4: Rating | F4: Meaning
A5: Q1 | B5: It was easy to log in and start using PrePal. | C5: Access and onboarding | E5: 1 | F5: Strongly Disagree
A6: Q2 | B6: The questionnaire instructions, fields, units, and response scales were clear. | C6: Input clarity | E6: 2 | F6: Disagree
A7: Q3 | B7: The model selected by PrePal matched my student stage and available academic data. | C7: Model-routing confidence | E7: 3 | F7: Neutral
A8: Q4 | B8: The predicted GPA was displayed clearly and was easy to understand. | C8: Prediction presentation | E8: 4 | F8: Agree
A9: Q5 | B9: The reasons provided for the predicted GPA were useful. | C9: Explainability | E9: 5 | F9: Strongly Agree
A10: Q6 | B10: The attendance, study-hour, sleep, and stress warnings were clear and relevant. | C10: Warning usefulness
A11: Q7 | B11: The DASS-21 screening process and its result wording were understandable and appropriate. | C11: Mental-health screening usability | E11: Data collection and interpretation notes
A12: Q8 | B12: The academic dashboard and visualizations were easy to interpret. | C12: Dashboard clarity | E12: 1 | F12: Keep raw participant entries unchanged. | G12: If a response needs correction, document the reason rather than silently changing the original observation.
A13: Q9 | B13: The AI chatbot provided helpful academic guidance. | C13: AI support usefulness | E13: 2 | F13: Use anonymous participant codes. | G13: Keep any consent documents or identity links outside this workbook under your approved research process.
A14: Q10 | B14: The calendar, reminders, and peer features were easy to use when applicable. | C14: Supporting features | E14: 3 | F14: Do not calculate model accuracy from UAT opinions alone. | G14: User testing evaluates correctness, routing, reliability, usability, and perceived reasonableness. Predictive accuracy requires real outcomes or an approved labelled validation dataset.
A15: Q11 | B15: The app responded quickly and remained stable during my test. | C15: Performance and reliability | E15: 4 | F15: Report sample size and device coverage. | G15: For the final report, state how many undergraduates, degree programmes, year levels, devices, and Android versions were represented.
A16: Q12 | B16: Overall, I would feel confident using PrePal during a semester. | C16: Overall acceptance | E16: 5 | F16: Report both numbers and comments. | G16: Summarize pass rate, defect severity, mean usability ratings, and recurring qualitative feedback themes.
E17: 6 | F17: Treat DASS-21 as screening support. | G17: Do not present software-test output as a medical diagnosis or collect unnecessary sensitive details.
